[22:31:35.084] INFO - Eliminando anteriores archivos (data/, players/)
[22:31:35.186] INFO - API endpoint https://api.laligafantasymarca.com/api/v3/player
[22:31:35.186] INFO - API endpoint market-values https://api.laligafantasymarca.com/api/v3/player/ID_JUGADOR/market-value
[22:31:38.379] ERROR - Jugador 64 [NO ENCONTRADO]
[22:31:38.903] ERROR - Jugador 52 [NO ENCONTRADO]
[22:32:35.665] CRITICAL - HTTPSConnectionPool(host='api.laligafantasymarca.com', port=443): Read timed out. (read timeout=30)
Traceback (most recent call last):
  File "C:\Users\Msi\AppData\Local\Packages\PythonSoftwareFoundation.Python.3.10_qbz5n2kfra8p0\LocalCache\local-packages\Python310\site-packages\urllib3\connectionpool.py", line 466, in _make_request
    six.raise_from(e, None)
  File "<string>", line 3, in raise_from
  File "C:\Users\Msi\AppData\Local\Packages\PythonSoftwareFoundation.Python.3.10_qbz5n2kfra8p0\LocalCache\local-packages\Python310\site-packages\urllib3\connectionpool.py", line 461, in _make_request
    httplib_response = conn.getresponse()
  File "C:\Program Files\WindowsApps\PythonSoftwareFoundation.Python.3.10_3.10.3056.0_x64__qbz5n2kfra8p0\lib\http\client.py", line 1375, in getresponse
    response.begin()
  File "C:\Program Files\WindowsApps\PythonSoftwareFoundation.Python.3.10_3.10.3056.0_x64__qbz5n2kfra8p0\lib\http\client.py", line 318, in begin
    version, status, reason = self._read_status()
  File "C:\Program Files\WindowsApps\PythonSoftwareFoundation.Python.3.10_3.10.3056.0_x64__qbz5n2kfra8p0\lib\http\client.py", line 279, in _read_status
    line = str(self.fp.readline(_MAXLINE + 1), "iso-8859-1")
  File "C:\Program Files\WindowsApps\PythonSoftwareFoundation.Python.3.10_3.10.3056.0_x64__qbz5n2kfra8p0\lib\socket.py", line 705, in readinto
    return self._sock.recv_into(b)
  File "C:\Program Files\WindowsApps\PythonSoftwareFoundation.Python.3.10_3.10.3056.0_x64__qbz5n2kfra8p0\lib\ssl.py", line 1274, in recv_into
    return self.read(nbytes, buffer)
  File "C:\Program Files\WindowsApps\PythonSoftwareFoundation.Python.3.10_3.10.3056.0_x64__qbz5n2kfra8p0\lib\ssl.py", line 1130, in read
    return self._sslobj.read(len, buffer)
TimeoutError: The read operation timed out

During handling of the above exception, another exception occurred:

Traceback (most recent call last):
  File "C:\Users\Msi\AppData\Local\Packages\PythonSoftwareFoundation.Python.3.10_qbz5n2kfra8p0\LocalCache\local-packages\Python310\site-packages\requests\adapters.py", line 489, in send
    resp = conn.urlopen(
  File "C:\Users\Msi\AppData\Local\Packages\PythonSoftwareFoundation.Python.3.10_qbz5n2kfra8p0\LocalCache\local-packages\Python310\site-packages\urllib3\connectionpool.py", line 798, in urlopen
    retries = retries.increment(
  File "C:\Users\Msi\AppData\Local\Packages\PythonSoftwareFoundation.Python.3.10_qbz5n2kfra8p0\LocalCache\local-packages\Python310\site-packages\urllib3\util\retry.py", line 550, in increment
    raise six.reraise(type(error), error, _stacktrace)
  File "C:\Users\Msi\AppData\Local\Packages\PythonSoftwareFoundation.Python.3.10_qbz5n2kfra8p0\LocalCache\local-packages\Python310\site-packages\urllib3\packages\six.py", line 770, in reraise
    raise value
  File "C:\Users\Msi\AppData\Local\Packages\PythonSoftwareFoundation.Python.3.10_qbz5n2kfra8p0\LocalCache\local-packages\Python310\site-packages\urllib3\connectionpool.py", line 714, in urlopen
    httplib_response = self._make_request(
  File "C:\Users\Msi\AppData\Local\Packages\PythonSoftwareFoundation.Python.3.10_qbz5n2kfra8p0\LocalCache\local-packages\Python310\site-packages\urllib3\connectionpool.py", line 468, in _make_request
    self._raise_timeout(err=e, url=url, timeout_value=read_timeout)
  File "C:\Users\Msi\AppData\Local\Packages\PythonSoftwareFoundation.Python.3.10_qbz5n2kfra8p0\LocalCache\local-packages\Python310\site-packages\urllib3\connectionpool.py", line 357, in _raise_timeout
    raise ReadTimeoutError(
urllib3.exceptions.ReadTimeoutError: HTTPSConnectionPool(host='api.laligafantasymarca.com', port=443): Read timed out. (read timeout=30)

During handling of the above exception, another exception occurred:

Traceback (most recent call last):
  File "C:\Users\Msi\Desktop\Proyectos\Fantasy-predictivo\fantasy_scraper.py", line 204, in main
    for _ in executor.map(multithread_scrape_player_aux, range(INDEX_INICIO_API, total_jugadores)):
  File "C:\Program Files\WindowsApps\PythonSoftwareFoundation.Python.3.10_3.10.3056.0_x64__qbz5n2kfra8p0\lib\concurrent\futures\_base.py", line 621, in result_iterator
    yield _result_or_cancel(fs.pop())
  File "C:\Program Files\WindowsApps\PythonSoftwareFoundation.Python.3.10_3.10.3056.0_x64__qbz5n2kfra8p0\lib\concurrent\futures\_base.py", line 319, in _result_or_cancel
    return fut.result(timeout)
  File "C:\Program Files\WindowsApps\PythonSoftwareFoundation.Python.3.10_3.10.3056.0_x64__qbz5n2kfra8p0\lib\concurrent\futures\_base.py", line 458, in result
    return self.__get_result()
  File "C:\Program Files\WindowsApps\PythonSoftwareFoundation.Python.3.10_3.10.3056.0_x64__qbz5n2kfra8p0\lib\concurrent\futures\_base.py", line 403, in __get_result
    raise self._exception
  File "C:\Program Files\WindowsApps\PythonSoftwareFoundation.Python.3.10_3.10.3056.0_x64__qbz5n2kfra8p0\lib\concurrent\futures\thread.py", line 58, in run
    result = self.fn(*self.args, **self.kwargs)
  File "C:\Users\Msi\Desktop\Proyectos\Fantasy-predictivo\fantasy_scraper.py", line 156, in multithread_scrape_player_aux
    response = requests.get(f"{PLAYERS_ENDPOINT}/{player_index}", timeout=REQUEST_TIMEOUT)
  File "C:\Users\Msi\AppData\Local\Packages\PythonSoftwareFoundation.Python.3.10_qbz5n2kfra8p0\LocalCache\local-packages\Python310\site-packages\requests\api.py", line 73, in get
    return request("get", url, params=params, **kwargs)
  File "C:\Users\Msi\AppData\Local\Packages\PythonSoftwareFoundation.Python.3.10_qbz5n2kfra8p0\LocalCache\local-packages\Python310\site-packages\requests\api.py", line 59, in request
    return session.request(method=method, url=url, **kwargs)
  File "C:\Users\Msi\AppData\Local\Packages\PythonSoftwareFoundation.Python.3.10_qbz5n2kfra8p0\LocalCache\local-packages\Python310\site-packages\requests\sessions.py", line 587, in request
    resp = self.send(prep, **send_kwargs)
  File "C:\Users\Msi\AppData\Local\Packages\PythonSoftwareFoundation.Python.3.10_qbz5n2kfra8p0\LocalCache\local-packages\Python310\site-packages\requests\sessions.py", line 701, in send
    r = adapter.send(request, **kwargs)
  File "C:\Users\Msi\AppData\Local\Packages\PythonSoftwareFoundation.Python.3.10_qbz5n2kfra8p0\LocalCache\local-packages\Python310\site-packages\requests\adapters.py", line 578, in send
    raise ReadTimeout(e, request=request)
requests.exceptions.ReadTimeout: HTTPSConnectionPool(host='api.laligafantasymarca.com', port=443): Read timed out. (read timeout=30)
