[23:30:58.420] INFO - Eliminando anteriores archivos (data/, players/)
[23:30:58.424] INFO - API endpoint https://api.laligafantasymarca.com/api/v3/player
[23:30:58.424] INFO - API endpoint market-values https://api.laligafantasymarca.com/api/v3/player/ID_JUGADOR/market-value
[23:30:58.717] ERROR - Jugador 63 [NO ENCONTRADO]
[23:30:58.734] ERROR - Jugador 54 [NO ENCONTRADO]
[23:30:58.924] ERROR - Jugador 64 [NO ENCONTRADO]
[23:30:59.153] ERROR - Jugador 66 [NO ENCONTRADO]
[23:30:59.239] ERROR - Jugador 60 [NO ENCONTRADO]
[23:30:59.285] ERROR - Jugador 61 [out_of_league]
[23:30:59.512] ERROR - Jugador 69 [NO ENCONTRADO]
[23:31:01.571] INFO - Escribiendo historial market-value del jugador 55 (47 values)
[23:31:01.574] INFO - Jugador 55 almacenado correctamente
[23:31:13.170] ERROR - Jugador 52 [NO ENCONTRADO]
[23:31:16.733] INFO - Escribiendo historial market-value del jugador 62 (47 values)
[23:31:16.739] INFO - Jugador 62 almacenado correctamente
[23:31:17.062] INFO - Escribiendo historial market-value del jugador 53 (47 values)
[23:31:17.067] INFO - Jugador 53 almacenado correctamente
[23:31:17.377] INFO - Escribiendo historial market-value del jugador 58 (47 values)
[23:31:17.381] INFO - Jugador 58 almacenado correctamente
[23:31:17.975] ERROR - Jugador 57 [NO ENCONTRADO]
[23:31:18.165] ERROR - Jugador 75 [out_of_league]
[23:31:20.292] INFO - Escribiendo historial market-value del jugador 67 (47 values)
[23:31:20.297] INFO - Jugador 67 almacenado correctamente
[23:31:22.594] INFO - Escribiendo historial market-value del jugador 77 (47 values)
[23:31:22.597] INFO - Jugador 77 almacenado correctamente
[23:31:24.683] INFO - Escribiendo historial market-value del jugador 59 (47 values)
[23:31:24.687] INFO - Jugador 59 almacenado correctamente
[23:31:25.792] ERROR - Jugador 71 [out_of_league]
[23:31:26.749] INFO - Escribiendo historial market-value del jugador 65 (47 values)
[23:31:26.752] INFO - Jugador 65 almacenado correctamente
[23:31:27.927] INFO - Escribiendo historial market-value del jugador 82 (47 values)
[23:31:27.932] INFO - Jugador 82 almacenado correctamente
[23:31:28.163] ERROR - Jugador 83 [NO ENCONTRADO]
[23:31:28.860] INFO - Escribiendo historial market-value del jugador 56 (47 values)
[23:31:28.865] INFO - Jugador 56 almacenado correctamente
[23:31:31.735] INFO - Escribiendo historial market-value del jugador 74 (47 values)
[23:31:31.740] INFO - Jugador 74 almacenado correctamente
[23:31:34.368] ERROR - Jugador 84 [out_of_league]
[23:31:34.751] ERROR - Jugador 87 [NO ENCONTRADO]
[23:31:36.045] INFO - Escribiendo historial market-value del jugador 73 (40 values)
[23:31:36.050] INFO - Jugador 73 almacenado correctamente
[23:31:36.914] ERROR - Jugador 89 [NO ENCONTRADO]
[23:31:42.068] INFO - Escribiendo historial market-value del jugador 91 (47 values)
[23:31:42.076] INFO - Jugador 91 almacenado correctamente
[23:31:45.190] ERROR - Jugador 88 [NO ENCONTRADO]
[23:31:46.764] INFO - Escribiendo historial market-value del jugador 81 (47 values)
[23:31:46.769] INFO - Jugador 81 almacenado correctamente
[23:31:48.154] INFO - Escribiendo historial market-value del jugador 68 (47 values)
[23:31:48.162] INFO - Jugador 68 almacenado correctamente
[23:31:48.395] ERROR - Jugador 96 [NO ENCONTRADO]
[23:31:50.152] INFO - Escribiendo historial market-value del jugador 72 (40 values)
[23:31:50.156] INFO - Jugador 72 almacenado correctamente
[23:31:50.686] ERROR - Jugador 79 [out_of_league]
[23:31:54.725] INFO - Escribiendo historial market-value del jugador 92 (47 values)
[23:31:54.730] INFO - Jugador 92 almacenado correctamente
[23:31:55.601] ERROR - Jugador 95 [out_of_league]
[23:31:56.354] INFO - Escribiendo historial market-value del jugador 78 (19 values)
[23:31:56.358] INFO - Jugador 78 almacenado correctamente
[23:31:57.074] ERROR - Jugador 85 [NO ENCONTRADO]
[23:31:59.948] INFO - Escribiendo historial market-value del jugador 80 (47 values)
[23:31:59.952] INFO - Jugador 80 almacenado correctamente
[23:32:05.282] INFO - Escribiendo historial market-value del jugador 90 (40 values)
[23:32:05.287] INFO - Jugador 90 almacenado correctamente
[23:32:09.757] INFO - Escribiendo historial market-value del jugador 86 (40 values)
[23:32:09.762] INFO - Jugador 86 almacenado correctamente
[23:32:12.188] ERROR - Jugador 94 [out_of_league]
[23:32:12.374] INFO - Escribiendo historial market-value del jugador 93 (47 values)
[23:32:12.379] INFO - Jugador 93 almacenado correctamente
[23:32:12.387] CRITICAL - HTTPSConnectionPool(host='api.laligafantasymarca.com', port=443): Read timed out. (read timeout=30)
Traceback (most recent call last):
  File "C:\Users\Msi\AppData\Local\Packages\PythonSoftwareFoundation.Python.3.10_qbz5n2kfra8p0\LocalCache\local-packages\Python310\site-packages\urllib3\connectionpool.py", line 466, in _make_request
    six.raise_from(e, None)
  File "<string>", line 3, in raise_from
  File "C:\Users\Msi\AppData\Local\Packages\PythonSoftwareFoundation.Python.3.10_qbz5n2kfra8p0\LocalCache\local-packages\Python310\site-packages\urllib3\connectionpool.py", line 461, in _make_request
    httplib_response = conn.getresponse()
  File "C:\Program Files\WindowsApps\PythonSoftwareFoundation.Python.3.10_3.10.3056.0_x64__qbz5n2kfra8p0\lib\http\client.py", line 1375, in getresponse
    response.begin()
  File "C:\Program Files\WindowsApps\PythonSoftwareFoundation.Python.3.10_3.10.3056.0_x64__qbz5n2kfra8p0\lib\http\client.py", line 318, in begin
    version, status, reason = self._read_status()
  File "C:\Program Files\WindowsApps\PythonSoftwareFoundation.Python.3.10_3.10.3056.0_x64__qbz5n2kfra8p0\lib\http\client.py", line 279, in _read_status
    line = str(self.fp.readline(_MAXLINE + 1), "iso-8859-1")
  File "C:\Program Files\WindowsApps\PythonSoftwareFoundation.Python.3.10_3.10.3056.0_x64__qbz5n2kfra8p0\lib\socket.py", line 705, in readinto
    return self._sock.recv_into(b)
  File "C:\Program Files\WindowsApps\PythonSoftwareFoundation.Python.3.10_3.10.3056.0_x64__qbz5n2kfra8p0\lib\ssl.py", line 1274, in recv_into
    return self.read(nbytes, buffer)
  File "C:\Program Files\WindowsApps\PythonSoftwareFoundation.Python.3.10_3.10.3056.0_x64__qbz5n2kfra8p0\lib\ssl.py", line 1130, in read
    return self._sslobj.read(len, buffer)
TimeoutError: The read operation timed out

During handling of the above exception, another exception occurred:

Traceback (most recent call last):
  File "C:\Users\Msi\AppData\Local\Packages\PythonSoftwareFoundation.Python.3.10_qbz5n2kfra8p0\LocalCache\local-packages\Python310\site-packages\requests\adapters.py", line 489, in send
    resp = conn.urlopen(
  File "C:\Users\Msi\AppData\Local\Packages\PythonSoftwareFoundation.Python.3.10_qbz5n2kfra8p0\LocalCache\local-packages\Python310\site-packages\urllib3\connectionpool.py", line 798, in urlopen
    retries = retries.increment(
  File "C:\Users\Msi\AppData\Local\Packages\PythonSoftwareFoundation.Python.3.10_qbz5n2kfra8p0\LocalCache\local-packages\Python310\site-packages\urllib3\util\retry.py", line 550, in increment
    raise six.reraise(type(error), error, _stacktrace)
  File "C:\Users\Msi\AppData\Local\Packages\PythonSoftwareFoundation.Python.3.10_qbz5n2kfra8p0\LocalCache\local-packages\Python310\site-packages\urllib3\packages\six.py", line 770, in reraise
    raise value
  File "C:\Users\Msi\AppData\Local\Packages\PythonSoftwareFoundation.Python.3.10_qbz5n2kfra8p0\LocalCache\local-packages\Python310\site-packages\urllib3\connectionpool.py", line 714, in urlopen
    httplib_response = self._make_request(
  File "C:\Users\Msi\AppData\Local\Packages\PythonSoftwareFoundation.Python.3.10_qbz5n2kfra8p0\LocalCache\local-packages\Python310\site-packages\urllib3\connectionpool.py", line 468, in _make_request
    self._raise_timeout(err=e, url=url, timeout_value=read_timeout)
  File "C:\Users\Msi\AppData\Local\Packages\PythonSoftwareFoundation.Python.3.10_qbz5n2kfra8p0\LocalCache\local-packages\Python310\site-packages\urllib3\connectionpool.py", line 357, in _raise_timeout
    raise ReadTimeoutError(
urllib3.exceptions.ReadTimeoutError: HTTPSConnectionPool(host='api.laligafantasymarca.com', port=443): Read timed out. (read timeout=30)

During handling of the above exception, another exception occurred:

Traceback (most recent call last):
  File "C:\Users\Msi\Desktop\Proyectos\Fantasy-predictivo\fantasy_scraper.py", line 204, in main
    for _ in executor.map(multithread_scrape_player_aux, range(INDEX_INICIO_API, total_jugadores)):
  File "C:\Program Files\WindowsApps\PythonSoftwareFoundation.Python.3.10_3.10.3056.0_x64__qbz5n2kfra8p0\lib\concurrent\futures\_base.py", line 621, in result_iterator
    yield _result_or_cancel(fs.pop())
  File "C:\Program Files\WindowsApps\PythonSoftwareFoundation.Python.3.10_3.10.3056.0_x64__qbz5n2kfra8p0\lib\concurrent\futures\_base.py", line 319, in _result_or_cancel
    return fut.result(timeout)
  File "C:\Program Files\WindowsApps\PythonSoftwareFoundation.Python.3.10_3.10.3056.0_x64__qbz5n2kfra8p0\lib\concurrent\futures\_base.py", line 451, in result
    return self.__get_result()
  File "C:\Program Files\WindowsApps\PythonSoftwareFoundation.Python.3.10_3.10.3056.0_x64__qbz5n2kfra8p0\lib\concurrent\futures\_base.py", line 403, in __get_result
    raise self._exception
  File "C:\Program Files\WindowsApps\PythonSoftwareFoundation.Python.3.10_3.10.3056.0_x64__qbz5n2kfra8p0\lib\concurrent\futures\thread.py", line 58, in run
    result = self.fn(*self.args, **self.kwargs)
  File "C:\Users\Msi\Desktop\Proyectos\Fantasy-predictivo\fantasy_scraper.py", line 156, in multithread_scrape_player_aux
    response = requests.get(f"{PLAYERS_ENDPOINT}/{player_index}", timeout=REQUEST_TIMEOUT)
  File "C:\Users\Msi\AppData\Local\Packages\PythonSoftwareFoundation.Python.3.10_qbz5n2kfra8p0\LocalCache\local-packages\Python310\site-packages\requests\api.py", line 73, in get
    return request("get", url, params=params, **kwargs)
  File "C:\Users\Msi\AppData\Local\Packages\PythonSoftwareFoundation.Python.3.10_qbz5n2kfra8p0\LocalCache\local-packages\Python310\site-packages\requests\api.py", line 59, in request
    return session.request(method=method, url=url, **kwargs)
  File "C:\Users\Msi\AppData\Local\Packages\PythonSoftwareFoundation.Python.3.10_qbz5n2kfra8p0\LocalCache\local-packages\Python310\site-packages\requests\sessions.py", line 587, in request
    resp = self.send(prep, **send_kwargs)
  File "C:\Users\Msi\AppData\Local\Packages\PythonSoftwareFoundation.Python.3.10_qbz5n2kfra8p0\LocalCache\local-packages\Python310\site-packages\requests\sessions.py", line 701, in send
    r = adapter.send(request, **kwargs)
  File "C:\Users\Msi\AppData\Local\Packages\PythonSoftwareFoundation.Python.3.10_qbz5n2kfra8p0\LocalCache\local-packages\Python310\site-packages\requests\adapters.py", line 578, in send
    raise ReadTimeout(e, request=request)
requests.exceptions.ReadTimeout: HTTPSConnectionPool(host='api.laligafantasymarca.com', port=443): Read timed out. (read timeout=30)
