[23:28:46.663] INFO - Eliminando anteriores archivos (data/, players/)
[23:28:46.677] INFO - API endpoint https://api.laligafantasymarca.com/api/v3/player
[23:28:46.677] INFO - API endpoint market-values https://api.laligafantasymarca.com/api/v3/player/ID_JUGADOR/market-value
[23:28:48.191] ERROR - Jugador 57 [NO ENCONTRADO]
[23:28:49.010] ERROR - Jugador 61 [out_of_league]
[23:28:51.598] INFO - Escribiendo historial market-value del jugador 62 (47 values)
[23:28:51.605] INFO - Jugador 62 almacenado correctamente
[23:28:55.543] ERROR - Jugador 60 [NO ENCONTRADO]
[23:28:57.665] ERROR - Jugador 54 [NO ENCONTRADO]
[23:28:58.510] ERROR - Jugador 52 [NO ENCONTRADO]
[23:28:59.548] INFO - Escribiendo historial market-value del jugador 59 (47 values)
[23:28:59.552] INFO - Jugador 59 almacenado correctamente
[23:28:59.991] ERROR - Jugador 70 [NO ENCONTRADO]
[23:29:04.110] INFO - Escribiendo historial market-value del jugador 55 (47 values)
[23:29:04.116] INFO - Jugador 55 almacenado correctamente
[23:29:05.154] ERROR - Jugador 63 [NO ENCONTRADO]
[23:29:05.316] INFO - Escribiendo historial market-value del jugador 65 (47 values)
[23:29:05.320] INFO - Jugador 65 almacenado correctamente
[23:29:08.527] ERROR - Jugador 71 [out_of_league]
[23:29:08.579] ERROR - Jugador 69 [NO ENCONTRADO]
[23:29:09.229] INFO - Escribiendo historial market-value del jugador 56 (47 values)
[23:29:09.234] INFO - Jugador 56 almacenado correctamente
[23:29:09.519] ERROR - Jugador 66 [NO ENCONTRADO]
[23:29:10.052] INFO - Escribiendo historial market-value del jugador 74 (47 values)
[23:29:10.057] INFO - Jugador 74 almacenado correctamente
[23:29:12.259] INFO - Escribiendo historial market-value del jugador 78 (19 values)
[23:29:12.264] INFO - Jugador 78 almacenado correctamente
[23:29:14.249] INFO - Escribiendo historial market-value del jugador 72 (40 values)
[23:29:14.254] INFO - Jugador 72 almacenado correctamente
[23:29:16.722] ERROR - Jugador 75 [out_of_league]
[23:29:22.096] INFO - Escribiendo historial market-value del jugador 53 (47 values)
[23:29:22.101] INFO - Jugador 53 almacenado correctamente
[23:29:23.612] INFO - Escribiendo historial market-value del jugador 82 (47 values)
[23:29:23.619] INFO - Jugador 82 almacenado correctamente
[23:29:24.907] ERROR - Jugador 79 [out_of_league]
[23:29:25.146] INFO - Escribiendo historial market-value del jugador 80 (47 values)
[23:29:25.151] INFO - Jugador 80 almacenado correctamente
[23:29:25.487] ERROR - Jugador 84 [out_of_league]
[23:29:30.488] INFO - Escribiendo historial market-value del jugador 77 (47 values)
[23:29:30.492] INFO - Jugador 77 almacenado correctamente
[23:29:31.286] ERROR - Jugador 76 [NO ENCONTRADO]
[23:29:32.135] ERROR - Jugador 88 [NO ENCONTRADO]
[23:29:32.582] INFO - Escribiendo historial market-value del jugador 73 (40 values)
[23:29:32.587] INFO - Jugador 73 almacenado correctamente
[23:29:34.149] INFO - Escribiendo historial market-value del jugador 58 (47 values)
[23:29:34.153] INFO - Jugador 58 almacenado correctamente
[23:29:34.549] ERROR - Jugador 83 [NO ENCONTRADO]
[23:29:35.084] ERROR - Jugador 89 [NO ENCONTRADO]
[23:29:42.003] INFO - Escribiendo historial market-value del jugador 86 (40 values)
[23:29:42.008] INFO - Jugador 86 almacenado correctamente
[23:29:42.120] ERROR - Jugador 85 [NO ENCONTRADO]
[23:29:42.158] INFO - Escribiendo historial market-value del jugador 90 (40 values)
[23:29:42.164] INFO - Jugador 90 almacenado correctamente
[23:29:42.277] INFO - Escribiendo historial market-value del jugador 81 (47 values)
[23:29:42.282] INFO - Jugador 81 almacenado correctamente
[23:29:57.406] INFO - Escribiendo historial market-value del jugador 92 (47 values)
[23:29:57.411] INFO - Jugador 92 almacenado correctamente
[23:29:59.430] INFO - Escribiendo historial market-value del jugador 93 (47 values)
[23:29:59.435] INFO - Jugador 93 almacenado correctamente
[23:30:00.211] INFO - Escribiendo historial market-value del jugador 91 (47 values)
[23:30:00.216] INFO - Jugador 91 almacenado correctamente
[23:30:03.571] ERROR - Jugador 94 [out_of_league]
[23:30:03.576] CRITICAL - HTTPSConnectionPool(host='api.laligafantasymarca.com', port=443): Read timed out. (read timeout=30)
Traceback (most recent call last):
  File "C:\Users\Msi\AppData\Local\Packages\PythonSoftwareFoundation.Python.3.10_qbz5n2kfra8p0\LocalCache\local-packages\Python310\site-packages\urllib3\connectionpool.py", line 466, in _make_request
    six.raise_from(e, None)
  File "<string>", line 3, in raise_from
  File "C:\Users\Msi\AppData\Local\Packages\PythonSoftwareFoundation.Python.3.10_qbz5n2kfra8p0\LocalCache\local-packages\Python310\site-packages\urllib3\connectionpool.py", line 461, in _make_request
    httplib_response = conn.getresponse()
  File "C:\Program Files\WindowsApps\PythonSoftwareFoundation.Python.3.10_3.10.3056.0_x64__qbz5n2kfra8p0\lib\http\client.py", line 1375, in getresponse
    response.begin()
  File "C:\Program Files\WindowsApps\PythonSoftwareFoundation.Python.3.10_3.10.3056.0_x64__qbz5n2kfra8p0\lib\http\client.py", line 318, in begin
    version, status, reason = self._read_status()
  File "C:\Program Files\WindowsApps\PythonSoftwareFoundation.Python.3.10_3.10.3056.0_x64__qbz5n2kfra8p0\lib\http\client.py", line 279, in _read_status
    line = str(self.fp.readline(_MAXLINE + 1), "iso-8859-1")
  File "C:\Program Files\WindowsApps\PythonSoftwareFoundation.Python.3.10_3.10.3056.0_x64__qbz5n2kfra8p0\lib\socket.py", line 705, in readinto
    return self._sock.recv_into(b)
  File "C:\Program Files\WindowsApps\PythonSoftwareFoundation.Python.3.10_3.10.3056.0_x64__qbz5n2kfra8p0\lib\ssl.py", line 1274, in recv_into
    return self.read(nbytes, buffer)
  File "C:\Program Files\WindowsApps\PythonSoftwareFoundation.Python.3.10_3.10.3056.0_x64__qbz5n2kfra8p0\lib\ssl.py", line 1130, in read
    return self._sslobj.read(len, buffer)
TimeoutError: The read operation timed out

During handling of the above exception, another exception occurred:

Traceback (most recent call last):
  File "C:\Users\Msi\AppData\Local\Packages\PythonSoftwareFoundation.Python.3.10_qbz5n2kfra8p0\LocalCache\local-packages\Python310\site-packages\requests\adapters.py", line 489, in send
    resp = conn.urlopen(
  File "C:\Users\Msi\AppData\Local\Packages\PythonSoftwareFoundation.Python.3.10_qbz5n2kfra8p0\LocalCache\local-packages\Python310\site-packages\urllib3\connectionpool.py", line 798, in urlopen
    retries = retries.increment(
  File "C:\Users\Msi\AppData\Local\Packages\PythonSoftwareFoundation.Python.3.10_qbz5n2kfra8p0\LocalCache\local-packages\Python310\site-packages\urllib3\util\retry.py", line 550, in increment
    raise six.reraise(type(error), error, _stacktrace)
  File "C:\Users\Msi\AppData\Local\Packages\PythonSoftwareFoundation.Python.3.10_qbz5n2kfra8p0\LocalCache\local-packages\Python310\site-packages\urllib3\packages\six.py", line 770, in reraise
    raise value
  File "C:\Users\Msi\AppData\Local\Packages\PythonSoftwareFoundation.Python.3.10_qbz5n2kfra8p0\LocalCache\local-packages\Python310\site-packages\urllib3\connectionpool.py", line 714, in urlopen
    httplib_response = self._make_request(
  File "C:\Users\Msi\AppData\Local\Packages\PythonSoftwareFoundation.Python.3.10_qbz5n2kfra8p0\LocalCache\local-packages\Python310\site-packages\urllib3\connectionpool.py", line 468, in _make_request
    self._raise_timeout(err=e, url=url, timeout_value=read_timeout)
  File "C:\Users\Msi\AppData\Local\Packages\PythonSoftwareFoundation.Python.3.10_qbz5n2kfra8p0\LocalCache\local-packages\Python310\site-packages\urllib3\connectionpool.py", line 357, in _raise_timeout
    raise ReadTimeoutError(
urllib3.exceptions.ReadTimeoutError: HTTPSConnectionPool(host='api.laligafantasymarca.com', port=443): Read timed out. (read timeout=30)

During handling of the above exception, another exception occurred:

Traceback (most recent call last):
  File "C:\Users\Msi\Desktop\Proyectos\Fantasy-predictivo\fantasy_scraper.py", line 204, in main
    for _ in executor.map(multithread_scrape_player_aux, range(INDEX_INICIO_API, total_jugadores)):
  File "C:\Program Files\WindowsApps\PythonSoftwareFoundation.Python.3.10_3.10.3056.0_x64__qbz5n2kfra8p0\lib\concurrent\futures\_base.py", line 621, in result_iterator
    yield _result_or_cancel(fs.pop())
  File "C:\Program Files\WindowsApps\PythonSoftwareFoundation.Python.3.10_3.10.3056.0_x64__qbz5n2kfra8p0\lib\concurrent\futures\_base.py", line 319, in _result_or_cancel
    return fut.result(timeout)
  File "C:\Program Files\WindowsApps\PythonSoftwareFoundation.Python.3.10_3.10.3056.0_x64__qbz5n2kfra8p0\lib\concurrent\futures\_base.py", line 451, in result
    return self.__get_result()
  File "C:\Program Files\WindowsApps\PythonSoftwareFoundation.Python.3.10_3.10.3056.0_x64__qbz5n2kfra8p0\lib\concurrent\futures\_base.py", line 403, in __get_result
    raise self._exception
  File "C:\Program Files\WindowsApps\PythonSoftwareFoundation.Python.3.10_3.10.3056.0_x64__qbz5n2kfra8p0\lib\concurrent\futures\thread.py", line 58, in run
    result = self.fn(*self.args, **self.kwargs)
  File "C:\Users\Msi\Desktop\Proyectos\Fantasy-predictivo\fantasy_scraper.py", line 156, in multithread_scrape_player_aux
    response = requests.get(f"{PLAYERS_ENDPOINT}/{player_index}", timeout=REQUEST_TIMEOUT)
  File "C:\Users\Msi\AppData\Local\Packages\PythonSoftwareFoundation.Python.3.10_qbz5n2kfra8p0\LocalCache\local-packages\Python310\site-packages\requests\api.py", line 73, in get
    return request("get", url, params=params, **kwargs)
  File "C:\Users\Msi\AppData\Local\Packages\PythonSoftwareFoundation.Python.3.10_qbz5n2kfra8p0\LocalCache\local-packages\Python310\site-packages\requests\api.py", line 59, in request
    return session.request(method=method, url=url, **kwargs)
  File "C:\Users\Msi\AppData\Local\Packages\PythonSoftwareFoundation.Python.3.10_qbz5n2kfra8p0\LocalCache\local-packages\Python310\site-packages\requests\sessions.py", line 587, in request
    resp = self.send(prep, **send_kwargs)
  File "C:\Users\Msi\AppData\Local\Packages\PythonSoftwareFoundation.Python.3.10_qbz5n2kfra8p0\LocalCache\local-packages\Python310\site-packages\requests\sessions.py", line 701, in send
    r = adapter.send(request, **kwargs)
  File "C:\Users\Msi\AppData\Local\Packages\PythonSoftwareFoundation.Python.3.10_qbz5n2kfra8p0\LocalCache\local-packages\Python310\site-packages\requests\adapters.py", line 578, in send
    raise ReadTimeout(e, request=request)
requests.exceptions.ReadTimeout: HTTPSConnectionPool(host='api.laligafantasymarca.com', port=443): Read timed out. (read timeout=30)
